[2024-09-16T00:07:42.728+0000] {local_task_job_runner.py:123} INFO - ::group::Pre task execution logs
[2024-09-16T00:07:42.751+0000] {taskinstance.py:2612} INFO - Dependencies all met for dep_context=non-requeueable deps ti=<TaskInstance: rasa_data_ingestion_dag.create_pet_table scheduled__2024-09-15T00:00:00+00:00 [queued]>
[2024-09-16T00:07:42.761+0000] {taskinstance.py:2612} INFO - Dependencies all met for dep_context=requeueable deps ti=<TaskInstance: rasa_data_ingestion_dag.create_pet_table scheduled__2024-09-15T00:00:00+00:00 [queued]>
[2024-09-16T00:07:42.762+0000] {taskinstance.py:2865} INFO - Starting attempt 2 of 3
[2024-09-16T00:07:42.775+0000] {taskinstance.py:2888} INFO - Executing <Task(SQLExecuteQueryOperator): create_pet_table> on 2024-09-15 00:00:00+00:00
[2024-09-16T00:07:42.783+0000] {warnings.py:112} WARNING - /home/***/.local/lib/python3.12/site-packages/***/task/task_runner/standard_task_runner.py:70: DeprecationWarning: This process (pid=568) is multi-threaded, use of fork() may lead to deadlocks in the child.
  pid = os.fork()

[2024-09-16T00:07:42.784+0000] {standard_task_runner.py:72} INFO - Started process 569 to run task
[2024-09-16T00:07:42.785+0000] {standard_task_runner.py:104} INFO - Running: ['***', 'tasks', 'run', 'rasa_data_ingestion_dag', 'create_pet_table', 'scheduled__2024-09-15T00:00:00+00:00', '--job-id', '42', '--raw', '--subdir', 'DAGS_FOLDER/dag_rasa.py', '--cfg-path', '/tmp/tmps89ywa6w']
[2024-09-16T00:07:42.786+0000] {standard_task_runner.py:105} INFO - Job 42: Subtask create_pet_table
[2024-09-16T00:07:42.837+0000] {task_command.py:467} INFO - Running <TaskInstance: rasa_data_ingestion_dag.create_pet_table scheduled__2024-09-15T00:00:00+00:00 [running]> on host 0d1d48929579
[2024-09-16T00:07:42.922+0000] {taskinstance.py:3131} INFO - Exporting env vars: AIRFLOW_CTX_DAG_OWNER='Eric Silveira' AIRFLOW_CTX_DAG_ID='rasa_data_ingestion_dag' AIRFLOW_CTX_TASK_ID='create_pet_table' AIRFLOW_CTX_EXECUTION_DATE='2024-09-15T00:00:00+00:00' AIRFLOW_CTX_TRY_NUMBER='2' AIRFLOW_CTX_DAG_RUN_ID='scheduled__2024-09-15T00:00:00+00:00'
[2024-09-16T00:07:42.923+0000] {taskinstance.py:731} INFO - ::endgroup::
[2024-09-16T00:07:42.927+0000] {sql.py:266} INFO - Executing: 
            CREATE TABLE IF NOT EXISTS pet (
            pet_id SERIAL PRIMARY KEY,
            name VARCHAR NOT NULL,
            pet_type VARCHAR NOT NULL,
            birth_date DATE NOT NULL,
            OWNER VARCHAR NOT NULL);
          
[2024-09-16T00:07:42.937+0000] {base.py:84} INFO - Retrieving connection 'conn_db_***'
[2024-09-16T00:07:42.980+0000] {base.py:84} INFO - Retrieving connection 'conn_db_***'
[2024-09-16T00:07:42.984+0000] {taskinstance.py:3310} ERROR - Task failed with exception
Traceback (most recent call last):
  File "/home/airflow/.local/lib/python3.12/site-packages/airflow/models/taskinstance.py", line 767, in _execute_task
    result = _execute_callable(context=context, **execute_callable_kwargs)
             ^^^^^^^^^^^^^^^^^^^^^^^^^^^^^^^^^^^^^^^^^^^^^^^^^^^^^^^^^^^^^
  File "/home/airflow/.local/lib/python3.12/site-packages/airflow/models/taskinstance.py", line 733, in _execute_callable
    return ExecutionCallableRunner(
           ^^^^^^^^^^^^^^^^^^^^^^^^
  File "/home/airflow/.local/lib/python3.12/site-packages/airflow/utils/operator_helpers.py", line 252, in run
    return self.func(*args, **kwargs)
           ^^^^^^^^^^^^^^^^^^^^^^^^^^
  File "/home/airflow/.local/lib/python3.12/site-packages/airflow/models/baseoperator.py", line 406, in wrapper
    return func(self, *args, **kwargs)
           ^^^^^^^^^^^^^^^^^^^^^^^^^^^
  File "/home/airflow/.local/lib/python3.12/site-packages/airflow/providers/common/sql/operators/sql.py", line 272, in execute
    output = hook.run(
             ^^^^^^^^^
  File "/home/airflow/.local/lib/python3.12/site-packages/airflow/providers/common/sql/hooks/sql.py", line 452, in run
    with self._create_autocommit_connection(autocommit) as conn:
  File "/usr/local/lib/python3.12/contextlib.py", line 137, in __enter__
    return next(self.gen)
           ^^^^^^^^^^^^^^
  File "/home/airflow/.local/lib/python3.12/site-packages/airflow/providers/common/sql/hooks/sql.py", line 574, in _create_autocommit_connection
    with closing(self.get_conn()) as conn:
                 ^^^^^^^^^^^^^^^
  File "/home/airflow/.local/lib/python3.12/site-packages/airflow/providers/postgres/hooks/postgres.py", line 176, in get_conn
    self.conn = psycopg2.connect(**conn_args)
                ^^^^^^^^^^^^^^^^^^^^^^^^^^^^^
  File "/home/airflow/.local/lib/python3.12/site-packages/psycopg2/__init__.py", line 122, in connect
    conn = _connect(dsn, connection_factory=connection_factory, **kwasync)
           ^^^^^^^^^^^^^^^^^^^^^^^^^^^^^^^^^^^^^^^^^^^^^^^^^^^^^^^^^^^^^^^
psycopg2.OperationalError: connection to server at "localhost" (::1), port 5438 failed: Connection refused
	Is the server running on that host and accepting TCP/IP connections?
connection to server at "localhost" (127.0.0.1), port 5438 failed: Connection refused
	Is the server running on that host and accepting TCP/IP connections?

[2024-09-16T00:07:43.003+0000] {taskinstance.py:1225} INFO - Marking task as UP_FOR_RETRY. dag_id=***_data_ingestion_dag, task_id=create_pet_table, run_id=scheduled__2024-09-15T00:00:00+00:00, execution_date=20240915T000000, start_date=20240916T000742, end_date=20240916T000743
[2024-09-16T00:07:43.018+0000] {taskinstance.py:340} INFO - ::group::Post task execution logs
[2024-09-16T00:07:43.018+0000] {standard_task_runner.py:124} ERROR - Failed to execute job 42 for task create_pet_table (connection to server at "localhost" (::1), port 5438 failed: Connection refused
	Is the server running on that host and accepting TCP/IP connections?
connection to server at "localhost" (127.0.0.1), port 5438 failed: Connection refused
	Is the server running on that host and accepting TCP/IP connections?
; 569)
Traceback (most recent call last):
  File "/home/airflow/.local/lib/python3.12/site-packages/airflow/task/task_runner/standard_task_runner.py", line 117, in _start_by_fork
    ret = args.func(args, dag=self.dag)
          ^^^^^^^^^^^^^^^^^^^^^^^^^^^^^
  File "/home/airflow/.local/lib/python3.12/site-packages/airflow/cli/cli_config.py", line 49, in command
    return func(*args, **kwargs)
           ^^^^^^^^^^^^^^^^^^^^^
  File "/home/airflow/.local/lib/python3.12/site-packages/airflow/utils/cli.py", line 115, in wrapper
    return f(*args, **kwargs)
           ^^^^^^^^^^^^^^^^^^
  File "/home/airflow/.local/lib/python3.12/site-packages/airflow/cli/commands/task_command.py", line 483, in task_run
    task_return_code = _run_task_by_selected_method(args, _dag, ti)
                       ^^^^^^^^^^^^^^^^^^^^^^^^^^^^^^^^^^^^^^^^^^^^
  File "/home/airflow/.local/lib/python3.12/site-packages/airflow/cli/commands/task_command.py", line 256, in _run_task_by_selected_method
    return _run_raw_task(args, ti)
           ^^^^^^^^^^^^^^^^^^^^^^^
  File "/home/airflow/.local/lib/python3.12/site-packages/airflow/cli/commands/task_command.py", line 341, in _run_raw_task
    return ti._run_raw_task(
           ^^^^^^^^^^^^^^^^^
  File "/home/airflow/.local/lib/python3.12/site-packages/airflow/utils/session.py", line 97, in wrapper
    return func(*args, session=session, **kwargs)
           ^^^^^^^^^^^^^^^^^^^^^^^^^^^^^^^^^^^^^^
  File "/home/airflow/.local/lib/python3.12/site-packages/airflow/models/taskinstance.py", line 3004, in _run_raw_task
    return _run_raw_task(
           ^^^^^^^^^^^^^^
  File "/home/airflow/.local/lib/python3.12/site-packages/airflow/models/taskinstance.py", line 273, in _run_raw_task
    TaskInstance._execute_task_with_callbacks(
  File "/home/airflow/.local/lib/python3.12/site-packages/airflow/models/taskinstance.py", line 3158, in _execute_task_with_callbacks
    result = self._execute_task(context, task_orig)
             ^^^^^^^^^^^^^^^^^^^^^^^^^^^^^^^^^^^^^^
  File "/home/airflow/.local/lib/python3.12/site-packages/airflow/models/taskinstance.py", line 3182, in _execute_task
    return _execute_task(self, context, task_orig)
           ^^^^^^^^^^^^^^^^^^^^^^^^^^^^^^^^^^^^^^^
  File "/home/airflow/.local/lib/python3.12/site-packages/airflow/models/taskinstance.py", line 767, in _execute_task
    result = _execute_callable(context=context, **execute_callable_kwargs)
             ^^^^^^^^^^^^^^^^^^^^^^^^^^^^^^^^^^^^^^^^^^^^^^^^^^^^^^^^^^^^^
  File "/home/airflow/.local/lib/python3.12/site-packages/airflow/models/taskinstance.py", line 733, in _execute_callable
    return ExecutionCallableRunner(
           ^^^^^^^^^^^^^^^^^^^^^^^^
  File "/home/airflow/.local/lib/python3.12/site-packages/airflow/utils/operator_helpers.py", line 252, in run
    return self.func(*args, **kwargs)
           ^^^^^^^^^^^^^^^^^^^^^^^^^^
  File "/home/airflow/.local/lib/python3.12/site-packages/airflow/models/baseoperator.py", line 406, in wrapper
    return func(self, *args, **kwargs)
           ^^^^^^^^^^^^^^^^^^^^^^^^^^^
  File "/home/airflow/.local/lib/python3.12/site-packages/airflow/providers/common/sql/operators/sql.py", line 272, in execute
    output = hook.run(
             ^^^^^^^^^
  File "/home/airflow/.local/lib/python3.12/site-packages/airflow/providers/common/sql/hooks/sql.py", line 452, in run
    with self._create_autocommit_connection(autocommit) as conn:
  File "/usr/local/lib/python3.12/contextlib.py", line 137, in __enter__
    return next(self.gen)
           ^^^^^^^^^^^^^^
  File "/home/airflow/.local/lib/python3.12/site-packages/airflow/providers/common/sql/hooks/sql.py", line 574, in _create_autocommit_connection
    with closing(self.get_conn()) as conn:
                 ^^^^^^^^^^^^^^^
  File "/home/airflow/.local/lib/python3.12/site-packages/airflow/providers/postgres/hooks/postgres.py", line 176, in get_conn
    self.conn = psycopg2.connect(**conn_args)
                ^^^^^^^^^^^^^^^^^^^^^^^^^^^^^
  File "/home/airflow/.local/lib/python3.12/site-packages/psycopg2/__init__.py", line 122, in connect
    conn = _connect(dsn, connection_factory=connection_factory, **kwasync)
           ^^^^^^^^^^^^^^^^^^^^^^^^^^^^^^^^^^^^^^^^^^^^^^^^^^^^^^^^^^^^^^^
psycopg2.OperationalError: connection to server at "localhost" (::1), port 5438 failed: Connection refused
	Is the server running on that host and accepting TCP/IP connections?
connection to server at "localhost" (127.0.0.1), port 5438 failed: Connection refused
	Is the server running on that host and accepting TCP/IP connections?

[2024-09-16T00:07:43.039+0000] {local_task_job_runner.py:266} INFO - Task exited with return code 1
[2024-09-16T00:07:43.064+0000] {taskinstance.py:3900} INFO - 0 downstream tasks scheduled from follow-on schedule check
[2024-09-16T00:07:43.065+0000] {local_task_job_runner.py:245} INFO - ::endgroup::
[2024-09-16T00:18:30.036+0000] {local_task_job_runner.py:123} INFO - ::group::Pre task execution logs
[2024-09-16T00:18:30.056+0000] {taskinstance.py:2612} INFO - Dependencies all met for dep_context=non-requeueable deps ti=<TaskInstance: rasa_data_ingestion_dag.create_pet_table scheduled__2024-09-15T00:00:00+00:00 [queued]>
[2024-09-16T00:18:30.064+0000] {taskinstance.py:2612} INFO - Dependencies all met for dep_context=requeueable deps ti=<TaskInstance: rasa_data_ingestion_dag.create_pet_table scheduled__2024-09-15T00:00:00+00:00 [queued]>
[2024-09-16T00:18:30.065+0000] {taskinstance.py:2865} INFO - Starting attempt 2 of 3
[2024-09-16T00:18:30.077+0000] {taskinstance.py:2888} INFO - Executing <Task(SQLExecuteQueryOperator): create_pet_table> on 2024-09-15 00:00:00+00:00
[2024-09-16T00:18:30.085+0000] {warnings.py:112} WARNING - /home/***/.local/lib/python3.12/site-packages/***/task/task_runner/standard_task_runner.py:70: DeprecationWarning: This process (pid=96) is multi-threaded, use of fork() may lead to deadlocks in the child.
  pid = os.fork()

[2024-09-16T00:18:30.086+0000] {standard_task_runner.py:72} INFO - Started process 97 to run task
[2024-09-16T00:18:30.087+0000] {standard_task_runner.py:104} INFO - Running: ['***', 'tasks', 'run', 'rasa_data_ingestion_dag', 'create_pet_table', 'scheduled__2024-09-15T00:00:00+00:00', '--job-id', '5', '--raw', '--subdir', 'DAGS_FOLDER/dag_rasa.py', '--cfg-path', '/tmp/tmpq0g9_x6w']
[2024-09-16T00:18:30.088+0000] {standard_task_runner.py:105} INFO - Job 5: Subtask create_pet_table
[2024-09-16T00:18:30.138+0000] {task_command.py:467} INFO - Running <TaskInstance: rasa_data_ingestion_dag.create_pet_table scheduled__2024-09-15T00:00:00+00:00 [running]> on host cb6fef0486e6
[2024-09-16T00:18:30.223+0000] {taskinstance.py:3131} INFO - Exporting env vars: AIRFLOW_CTX_DAG_OWNER='Eric Silveira' AIRFLOW_CTX_DAG_ID='rasa_data_ingestion_dag' AIRFLOW_CTX_TASK_ID='create_pet_table' AIRFLOW_CTX_EXECUTION_DATE='2024-09-15T00:00:00+00:00' AIRFLOW_CTX_TRY_NUMBER='2' AIRFLOW_CTX_DAG_RUN_ID='scheduled__2024-09-15T00:00:00+00:00'
[2024-09-16T00:18:30.224+0000] {taskinstance.py:731} INFO - ::endgroup::
[2024-09-16T00:18:30.227+0000] {sql.py:266} INFO - Executing: 
            CREATE TABLE IF NOT EXISTS pet (
            pet_id SERIAL PRIMARY KEY,
            name VARCHAR NOT NULL,
            pet_type VARCHAR NOT NULL,
            birth_date DATE NOT NULL,
            OWNER VARCHAR NOT NULL);
          
[2024-09-16T00:18:30.237+0000] {base.py:84} INFO - Retrieving connection 'conn_db_***'
[2024-09-16T00:18:30.246+0000] {base.py:84} INFO - Retrieving connection 'conn_db_***'
[2024-09-16T00:18:30.247+0000] {taskinstance.py:3310} ERROR - Task failed with exception
Traceback (most recent call last):
  File "/home/airflow/.local/lib/python3.12/site-packages/airflow/models/taskinstance.py", line 767, in _execute_task
    result = _execute_callable(context=context, **execute_callable_kwargs)
             ^^^^^^^^^^^^^^^^^^^^^^^^^^^^^^^^^^^^^^^^^^^^^^^^^^^^^^^^^^^^^
  File "/home/airflow/.local/lib/python3.12/site-packages/airflow/models/taskinstance.py", line 733, in _execute_callable
    return ExecutionCallableRunner(
           ^^^^^^^^^^^^^^^^^^^^^^^^
  File "/home/airflow/.local/lib/python3.12/site-packages/airflow/utils/operator_helpers.py", line 252, in run
    return self.func(*args, **kwargs)
           ^^^^^^^^^^^^^^^^^^^^^^^^^^
  File "/home/airflow/.local/lib/python3.12/site-packages/airflow/models/baseoperator.py", line 406, in wrapper
    return func(self, *args, **kwargs)
           ^^^^^^^^^^^^^^^^^^^^^^^^^^^
  File "/home/airflow/.local/lib/python3.12/site-packages/airflow/providers/common/sql/operators/sql.py", line 272, in execute
    output = hook.run(
             ^^^^^^^^^
  File "/home/airflow/.local/lib/python3.12/site-packages/airflow/providers/common/sql/hooks/sql.py", line 452, in run
    with self._create_autocommit_connection(autocommit) as conn:
  File "/usr/local/lib/python3.12/contextlib.py", line 137, in __enter__
    return next(self.gen)
           ^^^^^^^^^^^^^^
  File "/home/airflow/.local/lib/python3.12/site-packages/airflow/providers/common/sql/hooks/sql.py", line 574, in _create_autocommit_connection
    with closing(self.get_conn()) as conn:
                 ^^^^^^^^^^^^^^^
  File "/home/airflow/.local/lib/python3.12/site-packages/airflow/providers/postgres/hooks/postgres.py", line 176, in get_conn
    self.conn = psycopg2.connect(**conn_args)
                ^^^^^^^^^^^^^^^^^^^^^^^^^^^^^
  File "/home/airflow/.local/lib/python3.12/site-packages/psycopg2/__init__.py", line 122, in connect
    conn = _connect(dsn, connection_factory=connection_factory, **kwasync)
           ^^^^^^^^^^^^^^^^^^^^^^^^^^^^^^^^^^^^^^^^^^^^^^^^^^^^^^^^^^^^^^^
psycopg2.OperationalError: connection to server at "localhost" (::1), port 5438 failed: Connection refused
	Is the server running on that host and accepting TCP/IP connections?
connection to server at "localhost" (127.0.0.1), port 5438 failed: Connection refused
	Is the server running on that host and accepting TCP/IP connections?

[2024-09-16T00:18:30.263+0000] {taskinstance.py:1225} INFO - Marking task as UP_FOR_RETRY. dag_id=***_data_ingestion_dag, task_id=create_pet_table, run_id=scheduled__2024-09-15T00:00:00+00:00, execution_date=20240915T000000, start_date=20240916T001830, end_date=20240916T001830
[2024-09-16T00:18:30.278+0000] {taskinstance.py:340} INFO - ::group::Post task execution logs
[2024-09-16T00:18:30.279+0000] {standard_task_runner.py:124} ERROR - Failed to execute job 5 for task create_pet_table (connection to server at "localhost" (::1), port 5438 failed: Connection refused
	Is the server running on that host and accepting TCP/IP connections?
connection to server at "localhost" (127.0.0.1), port 5438 failed: Connection refused
	Is the server running on that host and accepting TCP/IP connections?
; 97)
Traceback (most recent call last):
  File "/home/airflow/.local/lib/python3.12/site-packages/airflow/task/task_runner/standard_task_runner.py", line 117, in _start_by_fork
    ret = args.func(args, dag=self.dag)
          ^^^^^^^^^^^^^^^^^^^^^^^^^^^^^
  File "/home/airflow/.local/lib/python3.12/site-packages/airflow/cli/cli_config.py", line 49, in command
    return func(*args, **kwargs)
           ^^^^^^^^^^^^^^^^^^^^^
  File "/home/airflow/.local/lib/python3.12/site-packages/airflow/utils/cli.py", line 115, in wrapper
    return f(*args, **kwargs)
           ^^^^^^^^^^^^^^^^^^
  File "/home/airflow/.local/lib/python3.12/site-packages/airflow/cli/commands/task_command.py", line 483, in task_run
    task_return_code = _run_task_by_selected_method(args, _dag, ti)
                       ^^^^^^^^^^^^^^^^^^^^^^^^^^^^^^^^^^^^^^^^^^^^
  File "/home/airflow/.local/lib/python3.12/site-packages/airflow/cli/commands/task_command.py", line 256, in _run_task_by_selected_method
    return _run_raw_task(args, ti)
           ^^^^^^^^^^^^^^^^^^^^^^^
  File "/home/airflow/.local/lib/python3.12/site-packages/airflow/cli/commands/task_command.py", line 341, in _run_raw_task
    return ti._run_raw_task(
           ^^^^^^^^^^^^^^^^^
  File "/home/airflow/.local/lib/python3.12/site-packages/airflow/utils/session.py", line 97, in wrapper
    return func(*args, session=session, **kwargs)
           ^^^^^^^^^^^^^^^^^^^^^^^^^^^^^^^^^^^^^^
  File "/home/airflow/.local/lib/python3.12/site-packages/airflow/models/taskinstance.py", line 3004, in _run_raw_task
    return _run_raw_task(
           ^^^^^^^^^^^^^^
  File "/home/airflow/.local/lib/python3.12/site-packages/airflow/models/taskinstance.py", line 273, in _run_raw_task
    TaskInstance._execute_task_with_callbacks(
  File "/home/airflow/.local/lib/python3.12/site-packages/airflow/models/taskinstance.py", line 3158, in _execute_task_with_callbacks
    result = self._execute_task(context, task_orig)
             ^^^^^^^^^^^^^^^^^^^^^^^^^^^^^^^^^^^^^^
  File "/home/airflow/.local/lib/python3.12/site-packages/airflow/models/taskinstance.py", line 3182, in _execute_task
    return _execute_task(self, context, task_orig)
           ^^^^^^^^^^^^^^^^^^^^^^^^^^^^^^^^^^^^^^^
  File "/home/airflow/.local/lib/python3.12/site-packages/airflow/models/taskinstance.py", line 767, in _execute_task
    result = _execute_callable(context=context, **execute_callable_kwargs)
             ^^^^^^^^^^^^^^^^^^^^^^^^^^^^^^^^^^^^^^^^^^^^^^^^^^^^^^^^^^^^^
  File "/home/airflow/.local/lib/python3.12/site-packages/airflow/models/taskinstance.py", line 733, in _execute_callable
    return ExecutionCallableRunner(
           ^^^^^^^^^^^^^^^^^^^^^^^^
  File "/home/airflow/.local/lib/python3.12/site-packages/airflow/utils/operator_helpers.py", line 252, in run
    return self.func(*args, **kwargs)
           ^^^^^^^^^^^^^^^^^^^^^^^^^^
  File "/home/airflow/.local/lib/python3.12/site-packages/airflow/models/baseoperator.py", line 406, in wrapper
    return func(self, *args, **kwargs)
           ^^^^^^^^^^^^^^^^^^^^^^^^^^^
  File "/home/airflow/.local/lib/python3.12/site-packages/airflow/providers/common/sql/operators/sql.py", line 272, in execute
    output = hook.run(
             ^^^^^^^^^
  File "/home/airflow/.local/lib/python3.12/site-packages/airflow/providers/common/sql/hooks/sql.py", line 452, in run
    with self._create_autocommit_connection(autocommit) as conn:
  File "/usr/local/lib/python3.12/contextlib.py", line 137, in __enter__
    return next(self.gen)
           ^^^^^^^^^^^^^^
  File "/home/airflow/.local/lib/python3.12/site-packages/airflow/providers/common/sql/hooks/sql.py", line 574, in _create_autocommit_connection
    with closing(self.get_conn()) as conn:
                 ^^^^^^^^^^^^^^^
  File "/home/airflow/.local/lib/python3.12/site-packages/airflow/providers/postgres/hooks/postgres.py", line 176, in get_conn
    self.conn = psycopg2.connect(**conn_args)
                ^^^^^^^^^^^^^^^^^^^^^^^^^^^^^
  File "/home/airflow/.local/lib/python3.12/site-packages/psycopg2/__init__.py", line 122, in connect
    conn = _connect(dsn, connection_factory=connection_factory, **kwasync)
           ^^^^^^^^^^^^^^^^^^^^^^^^^^^^^^^^^^^^^^^^^^^^^^^^^^^^^^^^^^^^^^^
psycopg2.OperationalError: connection to server at "localhost" (::1), port 5438 failed: Connection refused
	Is the server running on that host and accepting TCP/IP connections?
connection to server at "localhost" (127.0.0.1), port 5438 failed: Connection refused
	Is the server running on that host and accepting TCP/IP connections?

[2024-09-16T00:18:30.301+0000] {local_task_job_runner.py:266} INFO - Task exited with return code 1
[2024-09-16T00:18:30.324+0000] {taskinstance.py:3900} INFO - 0 downstream tasks scheduled from follow-on schedule check
[2024-09-16T00:18:30.326+0000] {local_task_job_runner.py:245} INFO - ::endgroup::
[2024-09-16T13:41:21.437+0000] {local_task_job_runner.py:123} INFO - ::group::Pre task execution logs
[2024-09-16T13:41:21.460+0000] {taskinstance.py:2612} INFO - Dependencies all met for dep_context=non-requeueable deps ti=<TaskInstance: rasa_data_ingestion_dag.create_pet_table scheduled__2024-09-15T00:00:00+00:00 [queued]>
[2024-09-16T13:41:21.470+0000] {taskinstance.py:2612} INFO - Dependencies all met for dep_context=requeueable deps ti=<TaskInstance: rasa_data_ingestion_dag.create_pet_table scheduled__2024-09-15T00:00:00+00:00 [queued]>
[2024-09-16T13:41:21.470+0000] {taskinstance.py:2865} INFO - Starting attempt 2 of 3
[2024-09-16T13:41:21.485+0000] {taskinstance.py:2888} INFO - Executing <Task(SQLExecuteQueryOperator): create_pet_table> on 2024-09-15 00:00:00+00:00
[2024-09-16T13:41:21.495+0000] {standard_task_runner.py:104} INFO - Running: ['***', 'tasks', 'run', 'rasa_data_ingestion_dag', 'create_pet_table', 'scheduled__2024-09-15T00:00:00+00:00', '--job-id', '5', '--raw', '--subdir', 'DAGS_FOLDER/dag_rasa.py', '--cfg-path', '/tmp/tmp0kwpu_lf']
[2024-09-16T13:41:21.498+0000] {standard_task_runner.py:105} INFO - Job 5: Subtask create_pet_table
[2024-09-16T13:41:21.503+0000] {logging_mixin.py:190} WARNING - /home/***/.local/lib/python3.12/site-packages/***/task/task_runner/standard_task_runner.py:70 DeprecationWarning: This process (pid=320) is multi-threaded, use of fork() may lead to deadlocks in the child.
[2024-09-16T13:41:21.504+0000] {standard_task_runner.py:72} INFO - Started process 321 to run task
[2024-09-16T13:41:21.543+0000] {task_command.py:467} INFO - Running <TaskInstance: rasa_data_ingestion_dag.create_pet_table scheduled__2024-09-15T00:00:00+00:00 [running]> on host 692c3b3b1c42
[2024-09-16T13:41:21.629+0000] {taskinstance.py:3131} INFO - Exporting env vars: AIRFLOW_CTX_DAG_OWNER='Eric Silveira' AIRFLOW_CTX_DAG_ID='rasa_data_ingestion_dag' AIRFLOW_CTX_TASK_ID='create_pet_table' AIRFLOW_CTX_EXECUTION_DATE='2024-09-15T00:00:00+00:00' AIRFLOW_CTX_TRY_NUMBER='2' AIRFLOW_CTX_DAG_RUN_ID='scheduled__2024-09-15T00:00:00+00:00'
[2024-09-16T13:41:21.630+0000] {taskinstance.py:731} INFO - ::endgroup::
[2024-09-16T13:41:21.632+0000] {sql.py:266} INFO - Executing: 
            CREATE TABLE IF NOT EXISTS public.pet (
            pet_id SERIAL PRIMARY KEY,
            name VARCHAR NOT NULL,
            pet_type VARCHAR NOT NULL,
            birth_date DATE NOT NULL,
            OWNER VARCHAR NOT NULL);
          
[2024-09-16T13:41:21.643+0000] {base.py:84} INFO - Retrieving connection 'conn_db_***'
[2024-09-16T13:41:21.653+0000] {base.py:84} INFO - Retrieving connection 'conn_db_***'
[2024-09-16T13:41:21.658+0000] {sql.py:509} INFO - Running statement: 
            CREATE TABLE IF NOT EXISTS public.pet (
            pet_id SERIAL PRIMARY KEY,
            name VARCHAR NOT NULL,
            pet_type VARCHAR NOT NULL,
            birth_date DATE NOT NULL,
            OWNER VARCHAR NOT NULL);
          , parameters: None
[2024-09-16T13:41:21.679+0000] {taskinstance.py:340} INFO - ::group::Post task execution logs
[2024-09-16T13:41:21.679+0000] {taskinstance.py:352} INFO - Marking task as SUCCESS. dag_id=***_data_ingestion_dag, task_id=create_pet_table, run_id=scheduled__2024-09-15T00:00:00+00:00, execution_date=20240915T000000, start_date=20240916T134121, end_date=20240916T134121
[2024-09-16T13:41:21.721+0000] {local_task_job_runner.py:266} INFO - Task exited with return code 0
[2024-09-16T13:41:21.744+0000] {taskinstance.py:3900} INFO - 0 downstream tasks scheduled from follow-on schedule check
[2024-09-16T13:41:21.746+0000] {local_task_job_runner.py:245} INFO - ::endgroup::
